Workbook
Name \0: #REF!
Name \1: #REF!
Name \3: #REF!
Name \4: #REF!
Name \a: #N/A
Name \B: #REF!
Name \B: #REF!
Name \c: #REF!
Name \c: #REF!
Name \c: #REF!
Name \c: #REF!
Name \c: #REF!
Name \c: #REF!
Name \c: #REF!
Name \c: #REF!
Name \c: #REF!
Name \c: #REF!
Name \c: #REF!
Name \d: #N/A
Name \e: #REF!
Name \e: #REF!
Name \e: #REF!
Name \e: #REF!
Name \e: #REF!
Name \e: #REF!
Name \e: #REF!
Name \e: #REF!
Name \e: #REF!
Name \e: #REF!
Name \e: #REF!
Name \f: #N/A
Name \FF: '[1]97 사업추정(WEKI)'!#REF!
Name \FG: [2]손익차총괄2!#REF!
Name \g: #REF!
Name \g: #REF!
Name \j: #REF!
Name \j: #REF!
Name \j: #REF!
Name \j: #REF!
Name \j: #REF!
Name \j: #REF!
Name \j: #REF!
Name \j: #REF!
Name \j: #REF!
Name \j: #REF!
Name \j: #REF!
Name \LL: #REF!
Name \M: #REF!
Name \n: #REF!
Name \n: #REF!
Name \n: #REF!
Name \n: #REF!
Name \n: #REF!
Name \n: #REF!
Name \n: #REF!
Name \n: #REF!
Name \n: #REF!
Name \n: #REF!
Name \n: #REF!
Name \o: #REF!

Sheet SZ Abstract (2)
A1: Abstract of SZ Plants | J1: District Wise Cost | M1: Division Wise Cost | R1: Rehab & O&M Cost
A2: Sr, No | B2: Division | C2: District | D2: Total No of Plants | E2: Functional | F2: Dys Fun + Abundand + Partly Functional | G2: Partly Fun | H2: Dys Fun | J2: Cost of Rehab Plants | K2: 1 Year O&M Cost of all Plants | L2: 3 Year O&M Cost of all Plants | M2: Divisions | N2: Total Cost | O2: 1 Year O&M Cost of all Plants | P2: 3 Year O&M Cost of all Plants | R2: 1 Year O&M Cost Rehab of all Plants | S2: 3 Year O&M Cost of all Plants
A3: 1 | B3: Multan | C3: Vehari | D3: 146 | E3: 135 | F3: 11 | G3: 0 | H3: 11 | J3: =D16*F3 -> #REF! | K3: =D18*D3 -> #REF! | L3: =D20*D3 -> #REF! | M3: Multan | N3: =SUM(J3:J6) -> #REF! | O3: =SUM(K3:K6) -> #REF! | P3: =SUM(L3:L6) -> #REF! | R3: =O3+N3 -> #REF! | S3: =P3+N3 -> #REF!
A4: 2 | C4: Lodhran | D4: 82 | E4: 64 | F4: 18 | G4: 2 | H4: 16 | J4: =D16*F4 -> #REF! | K4: =D18*D4 -> #REF! | L4: =D20*D4 -> #REF!
A5: 3 | C5: Khanewal | D5: 177 | E5: 157 | F5: 20 | G5: 1 | H5: 19 | J5: =D16*F5 -> #REF! | K5: =D18*D5 -> #REF! | L5: =D20*D5 -> #REF!
A6: 4 | C6: Multan | D6: 396 | E6: 273 | F6: 123 | G6: 29 | H6: 94 | J6: =D16*F6 -> #REF! | K6: =D18*D6 -> #REF! | L6: =D20*D6 -> #REF!
A7: 5 | B7: Bahawalpur | C7: Bahawalpur | D7: 190 | E7: 143 | F7: 47 | G7: 3 | H7: 44 | J7: =D16*F7 -> #REF! | K7: =D18*D7 -> #REF! | L7: =D20*D7 -> #REF! | M7: Bahawalpur | N7: =SUM(J7:J9) -> #REF! | O7: =SUM(K7:K9) -> #REF! | P7: =SUM(L7:L9) -> #REF! | R7: =O7+N7 -> #REF! | S7: =P7+N7 -> #REF!
A8: 6 | C8: Bahawalnagar | D8: 119 | E8: 98 | F8: 21 | G8: 0 | H8: 21 | J8: =D16*F8 -> #REF! | K8: =D18*D8 -> #REF! | L8: =D20*D8 -> #REF!
A9: 7 | C9: Rahimyar khan | D9: 203 | E9: 152 | F9: 51 | G9: 0 | H9: 51 | J9: =D16*F9 -> #REF! | K9: =D18*D9 -> #REF! | L9: =D20*D9 -> #REF!
A10: 8 | B10: DG Khan | C10: DG Khan | D10: 163 | E10: 63 | F10: 100 | G10: 16 | H10: 84 | J10: =D16*F10 -> #REF! | K10: =D18*D10 -> #REF! | L10: =D20*D10 -> #REF! | M10: DG Khan | N10: =SUM(J10:J13) -> #REF! | O10: =SUM(K10:K13) -> #REF! | P10: =SUM(L10:L13) -> #REF! | R10: =O10+N10 -> #REF! | S10: =P10+N10 -> #REF!
A11: 9 | C11: Rajanpur | D11: 63 | E11: 26 | F11: 37 | G11: 1 | H11: 36 | J11: =D16*F11 -> #REF! | K11: =D18*D11 -> #REF! | L11: =D20*D11 -> #REF!
A12: 10 | C12: Layyah | D12: 33 | E12: 14 | F12: 19 | G12: 14 | H12: 5 | J12: =D16*F12 -> #REF! | K12: =D18*D12 -> #REF! | L12: =D20*D12 -> #REF!
A13: 11 | C13: Muzafargarha | D13: 129 | E13: 22 | F13: 107 | G13: 42 | H13: 65 | J13: =D16*F13 -> #REF! | K13: =D18*D13 -> #REF! | L13: =D20*D13 -> #REF!
A14: Total # of Plants | D14: =SUM(D3:D13) -> 1701 | E14: =SUM(E3:E13) -> 1147 | F14: =SUM(F3:F13) -> 554 | G14: =SUM(G3:G13) -> 108 | H14: =SUM(H3:H13) -> 446 | J14: =SUM(J3:J13) -> #REF! | K14: =SUM(K3:K13) -> #REF! | L14: =SUM(L3:L13) -> #REF! | M14: Total | N14: =SUM(N3:N13) -> #REF! | O14: =SUM(O3:O13) -> #REF! | P14: =SUM(P3:P13) -> #REF! | R14: =SUM(R3:R13) -> #REF! | S14: =SUM(S3:S13) -> #REF!
A16: Average Rehab Cost of Plant | D16: =GS!#REF! -> #REF! | F16: Total Rehabilitaion Cost of 554 Plant | M16: =J14 -> #REF!
A18: Average O&M Cost of Plant for 1 Year | D18: ='SZ Abstract'!D18 -> #REF! | F18: Total Cost rehab + O&M of 1 Year for Total 1701 Plants | M18: =J14+K14 -> #REF!
A20: Average O&M Cost of Plant for 3 Year | D20: =D18*3 -> #REF! | F20: Total Cost rehab + O&M of 3 Year for Total 1701 Plants | M20: =J14+L14 -> #REF!
E27: =D16*(1782-542) -> #REF! | F27: =D18*(5179-542) -> #REF! | K27: =F27+E27 -> #REF!

Sheet SZ Abstract
A1: Abstract of SZ Plants | J1: District Wise Cost | M1: Division Wise Cost
A2: Sr, No | B2: Division | C2: District | D2: Total No of Plants | E2: Functional | F2: Dys Fun + Abundand + Partly Functional | G2: Partly Fun | H2: Dys Fun | J2: Cost of Rehab Plants | K2: 1 Year O&M Cost of all Plants | L2: 3 Year O&M Cost of all Plants | M2: Divisions | N2: Total Cost | O2: 1 Year O&M Cost of all Plants | P2: 3 Year O&M Cost of all Plants
A3: 1 | B3: Multan | C3: Vehari | D3: 146 | E3: 135 | F3: 11 | G3: 0 | H3: 11 | J3: =D16*F3 -> #REF! | K3: =D18*D3 -> #REF! | L3: =D20*D3 -> #REF! | M3: Multan | N3: =SUM(J3:J6) -> #REF! | O3: =SUM(K3:K6) -> #REF! | P3: =SUM(L3:L6) -> #REF!
A4: 2 | C4: Lodhran | D4: 82 | E4: 64 | F4: 18 | G4: 2 | H4: 16 | J4: =D16*F4 -> #REF! | K4: =D18*D4 -> #REF! | L4: =D20*D4 -> #REF!
A5: 3 | C5: Khanewal | D5: 177 | E5: 157 | F5: 20 | G5: 1 | H5: 19 | J5: =D16*F5 -> #REF! | K5: =D18*D5 -> #REF! | L5: =D20*D5 -> #REF!
A6: 4 | C6: Multan | D6: 396 | E6: 273 | F6: 123 | G6: 29 | H6: 94 | J6: =D16*F6 -> #REF! | K6: =D18*D6 -> #REF! | L6: =D20*D6 -> #REF!
A7: 5 | B7: Bahawalpur | C7: Bahawalpur | D7: 190 | E7: 143 | F7: 47 | G7: 3 | H7: 44 | J7: =D16*F7 -> #REF! | K7: =D18*D7 -> #REF! | L7: =D20*D7 -> #REF! | M7: Bahawalpur | N7: =SUM(J7:J9) -> #REF! | O7: =SUM(K7:K9) -> #REF! | P7: =SUM(L7:L9) -> #REF!
A8: 6 | C8: Bahawalnagar | D8: 119 | E8: 98 | F8: 21 | G8: 0 | H8: 21 | J8: =D16*F8 -> #REF! | K8: =D18*D8 -> #REF! | L8: =D20*D8 -> #REF!
A9: 7 | C9: Rahimyar khan | D9: 203 | E9: 152 | F9: 51 | G9: 0 | H9: 51 | J9: =D16*F9 -> #REF! | K9: =D18*D9 -> #REF! | L9: =D20*D9 -> #REF!
A10: 8 | B10: DG Khan | C10: DG Khan | D10: 163 | E10: 63 | F10: 100 | G10: 16 | H10: 84 | J10: =D16*F10 -> #REF! | K10: =D18*D10 -> #REF! | L10: =D20*D10 -> #REF! | M10: DG Khan | N10: =SUM(J10:J13) -> #REF! | O10: =SUM(K10:K13) -> #REF! | P10: =SUM(L10:L13) -> #REF!
A11: 9 | C11: Rajanpur | D11: 63 | E11: 26 | F11: 37 | G11: 1 | H11: 36 | J11: =D16*F11 -> #REF! | K11: =D18*D11 -> #REF! | L11: =D20*D11 -> #REF!
A12: 10 | C12: Layyah | D12: 33 | E12: 14 | F12: 19 | G12: 14 | H12: 5 | J12: =D16*F12 -> #REF! | K12: =D18*D12 -> #REF! | L12: =D20*D12 -> #REF!
A13: 11 | C13: Muzafargarha | D13: 129 | E13: 22 | F13: 107 | G13: 42 | H13: 65 | J13: =D16*F13 -> #REF! | K13: =D18*D13 -> #REF! | L13: =D20*D13 -> #REF!
A14: Total # of Plants | D14: =SUM(D3:D13) -> 1701 | E14: =SUM(E3:E13) -> 1147 | F14: =SUM(F3:F13) -> 554 | G14: =SUM(G3:G13) -> 108 | H14: =SUM(H3:H13) -> 446 | J14: =SUM(J3:J13) -> #REF! | K14: =SUM(K3:K13) -> #REF! | L14: =SUM(L3:L13) -> #REF! | M14: Total | N14: =SUM(N3:N13) -> #REF! | O14: =SUM(O3:O13) -> #REF! | P14: =SUM(P3:P13) -> #REF!
A16: Average Rehab Cost of Plant | D16: =Abstract!E29 -> #REF! | F16: Total Rehabilitaion Cost of 554 Plant | M16: =J14 -> #REF!
A18: Average O&M Cost of Plant for 1 Year | D18: ='O&M Abs 06 Months'!#REF! -> #REF! | F18: Total Cost rehab + O&M of 1 Year for Total 1701 Plants | M18: =J14+K14 -> #REF! | P18: 1518
A20: Average O&M Cost of Plant for 3 Year | D20: =D18*3 -> #REF! | F20: Total Cost rehab + O&M of 3 Year for Total 1701 Plants | M20: =J14+L14 -> #REF!

Sheet One Pager
A1: PUNJAB SAAF PANI AUTHORITY
A2: REHABILITATION & O&M OF DYSFUNCTIONAL WATER FILTRATION PLANTS INSTALLED BY MCL IN LAHORE
A4: ENGINEERING COST ESTIMATE
A5: Bill No | B5: Description | C5: Qty | D5: Unit Rate (Rs.) | E5: Amount (Rs.) | I5: Total no of Plants
A6: 1 | B6: Rehabilitation of Reverse Osmosis 500 LPH | C6: 4 | D6: ='R5'!#REF! -> #REF! | E6: =D6*C6 -> #REF! | F6: 6
A7: =A6+1 -> 2 | B7: Rehabilitation of Media Filtration 2000 LPH | C7: 20 | D7: =#REF! -> #REF! | E7: =D7*C7 -> #REF! | F7: 21
A8: =A7+1 -> 3 | B8: Rehabilitation of Ultra Filtration 4000 LPH | C8: 29 | D8: ='U4'!#REF! -> #REF! | E8: =D8*C8 -> #REF! | F8: 14 | G8: Functional Plants Included
A9: =A8+1 -> 4 | B9: Rehabilitation of Ultra Filtration 2000 LPH | C9: 2 | D9: ='U2'!#REF! -> #REF! | E9: =D9*C9 -> #REF! | H9: =(SUM(D6:D10)/5) -> #REF!
A10: =A9+1 -> 5 | B10: Rehabilitation of Ultra Filtration 1000 LPH | C10: 3 | D10: ='UF 1 Rehab'!G39 -> 0 | E10: =C10*D10 -> 0 | G10: =1025000*59 -> 60475000
A11: =A10+1 -> 6 | B11: Installation of Ultra Filtration 4000 LPH | C11: 4 | D11: 3663400 | E11: =C11*D11 -> 14653600
A12: =A11+1 -> 7 | B12: Installation of Reverese Osmosis 2000 LPH | C12: 1 | D12: 2831355 | E12: =C12*D12 -> 2831355
A13: =A12+1 -> 8 | B13: New Bore Holes | C13: =34*70% -> 23.8 | D13: =#REF! -> #REF! | E13: =D13*C13 -> #REF! | I13: =E27 -> 0
A14: =A13+1 -> 9 | B14: Washing of Bore Holes | C14: =30*85% -> 25.5 | D14: =WB!F7 -> 0 | E14: =D14*C14 -> 0
A15: =A14+1 -> 10 | B15: Rehabilitation of Pre Fab Work | C15: =49*65% -> 31.85 | D15: 100000 | E15: =D15*C15 -> 3185000
A16: =A15+1 -> 11 | B16: Rehabilitation of Civil Work | C16: 6 | D16: ='B8 Civil'!N54 -> 71461.12 | E16: =D16*C16 -> 428766.72
A17: =A16+1 -> 12 | B17: Water Analysis Reports | C17: 126 | D17: ='Rate Analysis'!F434 -> 5100 | E17: =D17*C17 -> 642600 | H17: Des | I17: Rehab | J17: Abnd | K17: Total Dist Plants | L17: Fun | P17: 43 | Q17: No of Plants | S17: 190
A18: Total: - | E18: =SUM(E6:E17) -> #REF! | H18: RO 500 LPH | I18: 0 | J18: 0 | P18: RO
A19: 6 Months O&M for 63 No. MCL Plants in Lahore Disctrict | E19: =SUM('O&M Abs 06 Months'!G35)*116% -> 21822102
B20: Total Capital Cost | E20: =E18 -> #REF! | H20: RO 1000 LPH | I20: 27 | J20: 2 | L20: 5 | M20: Per Plant Avg | N20: 150000 | P20: =SUM(I18:J22) -> 30 | Q20: RO | R20: 500 LPH | S20: 14
B21: Add 5% PRA | E21: =E20*5% -> #REF! | H21: RO 2000 LPH | I21: 0 | J21: 1 | L21: 0 | P21: UF | Q21: RO | R21: 1000 LPH | S21: 64
B22: Contingencies & Petty Charges 2% | E22: =E20*2% -> #REF! | M22: Total | N22: =N20*I28 -> 9000000 | P22: =SUM(I24:J26) -> 41 | Q22: RO | R22: 2000 LPH | S22: 68
B23: Resident Supervision 1.5% | E23: =E20*1.5% -> #REF!
B24: Electricity Charges & New Electricity Connections / Outstanding Bills | E24: =GA!E11 -> 33708000 | H24: UF 1000 LPH | I24: 0 | P24: MF | Q24: RO | R24: 4000 LPH | S24: 8
B25: Grand Total | E25: =SUM(E19:E24) -> #REF! | H25: UF 2000 LPH | I25: 33 | J25: 8 | L25: 5 | P25: =SUM(I27:J27) -> 0 | Q25: UF | R25: 1000 LPH | S25: 5
Q26: UF | R26: 2000 LPH | S26: 21
A28: Deputy Manager (P&MC) - CZ | C28: Director Planning | H28: Total | I28: =SUM(I18:I27) -> 60 | J28: =SUM(J18:J27) -> 11 | L28: =SUM(L18:L27) -> 10 | Q28: MF | R28: 1000 LPH
A29: Punjab Saaf Pani Authroity | C29: Punjab Saaf Pani Authroity | Q29: MF | R29: 2000 LPH | S29: 9
H30: Total | I30: =I28+J28 -> 71 | Q30: MF | R30: 4000 LPH
A31: Chief Engineer /DG Projects | H31: Functional | I31: =L28 -> 10 | Q31: No of Plants | S31: =SUM(S20:S30) -> 189
A32: Punjab Saaf Pani Authroity | H32: Total Plants | I32: =I31+I30 -> 81
I36: 80 Plants | J36: =E26 -> 0 | K36: =J36/1000000 -> 0
I37: 82 Plants | J37: ='[71]Abstract 2'!$E$22 -> 86073636 | K37: =J37/1000000 -> 86.073636
I38: Total | J38: =SUM(J36:J37) -> 86073636 | K38: =J38/1000000 -> 86.073636
I39: in millions | J39: =J38/1000000 -> 86.073636
I41: Total | J41: 206
I42: Already Estimated | J42: 80
I43: Lost | J43: 10
I44: Rehab by WASA | J44: 34
J45: =J41-J42-J43-J44 -> 82
I193: s
...

Sheet Gen Abstract 6 Months
A1: PUNJAB SAAF PANI AUTHORITY
A2: REHABILITATION & O&M OF DYSFUNCTIONAL WATER FILTRATION PLANTS INSTALLED BY MCL IN LAHORE
A4: ENGINEERING COST ESTIMATE
A5: No | B5: Description | E5: Amount (Rs.) in Million | H5: Total no of Plants
A6: 1 | B6: REHABILITATION OF DYSFUNCTIONAL WATER FILTRATION PLANTS INSTALLED BY MCL IN LAHORE | E6: =GS!E26 -> 0 | F6: =D6*28 -> 0 | G6: 18 | H6: RO | I6: =SUM(H7:I10) -> 23 | J6: =SUM(K7:K9) -> 11 | K6: =SUM(I6:J6) -> 34
B7: Total Capital Cost | E7: =E6 -> 0
B8: Add 5% PRA | E8: =E7*5% -> 0
B9: Contingencies & Petty Charges 2% | E9: =E6*2% -> 0 | G9: RO 2000 LPH | H9: 19 | I9: 4 | K9: 11 | O9: UF | P9: RO | Q9: 1000 LPH | R9: 64
B10: Resident Supervision 1.5% | E10: =E6*1.5% -> 0 | L10: Total | M10: =#REF!*H17 -> #REF! | O10: =SUM(H13:I15) -> 9 | P10: RO | Q10: 2000 LPH | R10: 68
B11: Electricity Charges & New Electricity Connections / Outstanding Bills | E11: =SUM('Electricity Charges 06 Months'!D6:F6) -> 13175000
B12: 6 Months O&M for MCL Plants including 16% PRA | E12: =SUM('O&M Abs 06 Months'!G35)*116% -> 21822102
B13: Grand Total | E13: =SUM(E7:E12) -> 34997102 | F13: =E13-#REF! -> #REF! | G13: UF 1000 LPH | H13: 9 | O13: MF | P13: RO | Q13: 4000 LPH | R13: 8
F14: =#REF!/70 -> #REF!
C15: Assistant Manager (P&MC) - CZ | P15: UF | Q15: 2000 LPH | R15: 21
F16: =108.47+#REF! -> #REF! | G16: MF 2000 LPH | P16: UF | Q16: 4000 LPH | R16: 1
G17: Total | H17: =SUM(H7:H16) -> 28 | I17: =SUM(I7:I16) -> 4 | K17: =SUM(K7:K16) -> 11 | P17: MF | Q17: 1000 LPH
P18: MF | Q18: 2000 LPH | R18: 9
A19: Deputy Manager (P&MC) - CZ | C19: Director Planning | G19: Total | H19: =H17+I17 -> 32 | P19: MF | Q19: 4000 LPH
G20: Functional | H20: =K17 -> 11 | P20: No of Plants | R20: =SUM(R9:R19) -> 171
G21: Total Plants | H21: =H20+H19 -> 43
A25: Chief Engineer/ D.G (O&M) | H25: 80 Plants | I25: =E15 -> 0 | J25: =I25/1000000 -> 0
H26: 82 Plants | I26: ='[71]Abstract 2'!$E$22 -> 86073636 | J26: =I26/1000000 -> 86.073636
H27: Total | I27: =SUM(I25:I26) -> 86073636 | J27: =I27/1000000 -> 86.073636
H30: in millions | I30: =I27/1000000 -> 86.073636
H32: Total | I32: 206
H33: Already Estimated | I33: 80
H34: Lost | I34: 10
H35: Rehab by WASA | I35: 34
I36: =I32-I33-I34-I35 -> 82
H184: s
E194: 24900
E204: 35300
A212: RO Feed Pump Repair 4000 LPH
B214: Repair & maintenance of RO Feed water pump 8000 LPH, for 4000 LPH RO Plant, complete in all respect | E214: 46700
E224: 23950
E234: 36100
E244: 44900
A252: RO High Pressure Pump Repair 4000 LPH
B254: Repair & maintenance of RO High Pressure pump 8000 LPH, for 4000 LPH RO Plant, complete in all respect | E254: 56700

Sheet GA
A1: PUNJAB SAAF PANI AUTHORITY
A2: REHABILITATION & O&M OF DYSFUNCTIONAL WATER FILTRATION PLANTS INSTALLED IN DIVISON FAISALABAD
A4: ENGINEERING COST ESTIMATE
A5: No | B5: Description | E5: Amount (Rs.) in Million
A6: 1 | B6: =A2 -> REHABILITATION & O&M OF DYSFUNCTIONAL WATER FILTRATION PLANTS INSTALLED IN DIVISON FAISALABAD | E6: =GS!E26 -> 0 | F6: =D6*28 -> 0
B7: Total Capital Cost | E7: =E6 -> 0
B8: Add 5% PRA | E8: =E7*5% -> 0 | F8: =E7+E8+E12 -> 0
B9: Contingencies & Petty Charges 2% | E9: =E6*2% -> 0 | F9: =F8*2% -> 0
B10: Resident Supervision 1.5% | E10: =E6*1.5% -> 0
B11: Electricity Charges & New Electricity Connections / Outstanding Bills | E11: ='EC 06'!D5+'EC 06'!E5+'EC 06'!F5 -> 33708000
B12: O&M for WFP Plants including 16% PRA | E12: ='O&M 06'!G43*116% -> 0
B13: Grand Total | E13: =SUM(E7:E12) -> 33708000
C15: Assistant Manager (P&MC) - CZ
C16: Punjab Saaf Pani Authority
A19: Deputy Manager (P&MC) - CZ | C19: Director (P&QC) CZ
A20: Punjab Saaf Pani Authority | C20: Punjab Saaf Pani Authority
E192: 24900
E202: 35300
A210: RO Feed Pump Repair 4000 LPH
B212: Repair & maintenance of RO Feed water pump 8000 LPH, for 4000 LPH RO Plant, complete in all respect | E212: 46700
E222: 23950
E232: 36100
E242: 44900
A250: RO High Pressure Pump Repair 4000 LPH
B252: Repair & maintenance of RO High Pressure pump 8000 LPH, for 4000 LPH RO Plant, complete in all respect | E252: 56700

Sheet GS
A1: PUNJAB SAAF PANI AUTHORITY
A2: =GA!A2 -> REHABILITATION & O&M OF DYSFUNCTIONAL WATER FILTRATION PLANTS INSTALLED IN DIVISON FAISALABAD
A4: BILL OF QUANTITY
A5: Bill No | B5: Description | C5: Qty | D5: Unit Rate (Rs.) | E5: Amount (Rs.)
A6: 1 | B6: Rehabilitation of Reverse Osmosis 500 LPH | C6: 1 | F6: 152 | G6: =39+58+55 -> 152
A7: 2 | B7: Rehabilitation of Reverse Osmosis 1000 LPH | C7: =41+6+3 -> 50
A8: 3 | B8: Rehabilitation of Reverse Osmosis 2000 LPH | C8: =45+2+1 -> 48
A9: 4 | B9: Rehabilitation of Ultra Filtration 4000 LPH | C9: 9
A10: 5 | B10: Rehabilitation of Ultra Filtration 2000 LPH | C10: =2+1 -> 3
A11: 6 | B11: Rehabilitation of Ultra Filtration 1000 LPH | C11: =3+4 -> 7
A12: 7 | B12: Installation of Ultra Filtration 2000 LPH | C12: 1
A13: 8 | B13: Installation of Reverse Osmosis 500 LPH | C13: 4
A14: 9 | B14: Installation of Reverse Osmosis 2000 LPH | C14: 9
A15: 10 | B15: Installation of Reverse Osmosis 1000 LPH | C15: 6
A16: 11 | B16: New Bore Holes | C16: 60
A17: 12 | B17: Development of Bore Hole | C17: 40
A18: 13 | B18: Injection Well | C18: 12
A19: 14 | B19: Rehabilitation of Pre Fab Work (Faisalabad) | C19: 12
A20: 15 | B20: Rehabilitation of Civil Work (Faisalabad) | C20: 96
A21: 16 | B21: Rehabilitation of Civil Work (Chiniot) | C21: 4
A22: 17 | B22: Rehabilitation of Civil Work (Jhang) | C22: 19
A23: 18 | B23: Rehabilitation of Civil Work (Toba Tek Singh) | C23: 2
... A25: 20 | B25: Water Analysis Reports | C25: 138
A26: Sub Total
A27: Add 5% PRA
A28: Sub Total (A) (Sub Total + 5% PRA)
A29: 06 months O&M for WFP Plants excluding Electricity Charges
A30: Sub Total (B) (06 months O&M)
A31: Add 16% PRA on Sub Total (B)
A32: Sub Total (C) (Sub Total B + 16% PRA)
A33: Grand Total (A+B+C)
E207: 24900
E217: 35300
A225: RO Feed Pump Repair 4000 LPH
B227: Repair & maintenance of RO Feed water pump 8000 LPH, for 4000 LPH RO Plant, complete in all respect | E227: 46700
E237: 23950
E247: 36100
E257: 44900
A265: RO High Pressure Pump Repair 4000 LPH
B267: Repair & maintenance of RO High Pressure pump 8000 LPH, for 4000 LPH RO Plant, complete in all respect | E267: 56700

Sheet Abstract
A1: PUNJAB AAB-E-PAK AUTHORITY
A2: REHABILITATION OF WATER FILTRATION PLANTS IN DISTRICT BAHAWALPUR
A4: Rough Cost Estimate for 47 Dysfunctional & 143 functional Plants: Total 190 Plants
A5: Sr. No | B5: Description | C5: Qty | D5: Per Unit | E5: Amount (Rs.) | H5: Total no of Plants
A6: 1 | B6: ='RO Rehab 500LPH'!A3 -> REHABLITATION OF RO PLANT 500 LPH | C6: =H21 -> 0 | D6: =E6/C6 -> #REF! | E6: ='RO Rehab 500LPH'!G42 -> #REF!
A7: 2 | B7: ='R5'!#REF! -> #REF! | C7: =H22 -> 20 | D7: =E7/C7 -> #REF! | E7: ='R5'!#REF! -> #REF! | H7: RO | I7: =SUM(H21:I24) -> 31
A8: 3 | B8: ='Bill No 2 RO 2000 Rehab'!A3 -> LAHORE DISTRICT | C8: =H23 -> 7 | D8: =E8/C8 -> #REF! | E8: ='Bill No 2 RO 2000 Rehab'!G44 -> #REF!
A9: 4 | B9: ='Bill No 3 UF 1000 Rehab'!A3 -> LAHORE DISTRICT | C9: =H25 -> 3 | D9: =E9/C9 -> #REF! | E9: ='Bill No 3 UF 1000 Rehab'!G41 -> #REF! | H9: UF | I9: =SUM(H25:I27) -> 41 | N9: =600/185 -> 3.2432432
A10: 5 | B10: ='U2'!#REF! -> #REF! | C10: =H26 -> 33 | D10: =E10/C10 -> #REF! | E10: ='U2'!#REF! -> #REF! | H10: MF | I10: =H28 -> 0
A11: 6 | B11: ='New RO500'!A2 -> INSTALATION OF RO 500 LPH WFP | C11: =I21 -> 0 | D11: ='New RO500'!F7 -> 1258666.5 | E11: =D11*C11 -> 0
A12: 7 | B12: ='Bill no 3 RO 1000 New'!A2 -> LAHORE DISTRICT | C12: =I22 -> 3 | D12: ='Bill no 3 RO 1000 New'!#REF! -> #REF! | E12: =D12*C12 -> #REF!
A13: 8 | B13: ='Bill No 4 RO 2000 New'!#REF! -> #REF! | C13: =I23 -> 1 | D13: ='Bill No 4 RO 2000 New'!#REF! -> #REF! | E13: =D13*C13 -> #REF!
A14: 9 | B14: ='Bill No 5 UF 2000 New'!#REF! -> #REF! | C14: =I26 -> 5 | D14: ='Bill No 5 UF 2000 New'!#REF! -> #REF! | E14: =D14*C14 -> #REF!
A15: 10 | B15: ='NEW MF 2000'!A2 -> INSTALATION OF MF 2000 LPH WFP | C15: =I28 -> 0 | D15: ='NEW MF 2000'!F7 -> 669243.75 | E15: =D15*C15 -> 0
A16: 11 | B16: New Bore Holes | C16: =H31*10% -> 7.2 | D16: =#REF! -> #REF! | E16: =D16*C16 -> #REF!
A17: 12 | B17: =WB!A4 -> Bill No 12:Development of Bore Holes | C17: =H31*10% -> 7.2 | D17: =WB!#REF! -> #REF! | E17: =D17*C17 -> #REF!
A18: 13 | B18: Repair of Civil Work | C18: =H31*30% -> 21.6 | D18: ='B8 Civil'!N54 -> 71461.12 | E18: =D18*C18 -> 1543560.2 | I18: =E21-F21 -> #REF!
A19: 14 | B19: Injection Well for Brine | C19: =SUM(H21:H23)*10% -> 2.7 | D19: ='Injection well'!G27 -> 0 | E19: =D19*C19 -> 0
A20: 15 | B20: Water Analysis Reports | C20: =2*H31 -> 144 | D20: ='Rate Analysis'!F434 -> 5100 | E20: =D20*C20 -> 734400 | G20: Des | H20: Rehab | I20: Abnd | J20: Total Dist Plants | L20: Outstanding Electricity Charges | O20: 43 | P20: No of Plants | R20: 190
A21: Total: - | E21: =SUM(E6:E20) -> #REF! | F21: =GS!E26 -> 0 | G21: RO 500 LPH | H21: 0 | I21: 0 | O21: RO
B22: Contingencies & Petty Charges 2% | E22: =F21*2% -> 0 | G22: RO 1000 LPH | H22: 20 | I22: 3 | L22: Per Plant Avg | M22: 150000 | O22: =SUM(H21:I24) -> 31 | P22: RO | Q22: 500 LPH | R22: 14
B23: Design & Resident Supervision 3% | E23: =F21*3% -> 0 | G23: RO 2000 LPH | H23: 7 | I23: 1 | O23: UF | P23: RO | Q23: 1000 LPH | R23: 64
B24: Electricity Charges | E24: {='O&M Abs 06 Months'!#REF!} -> #REF! | F24: #REF! | G24: #REF! | L24: Total | M24: =M22*H29 -> 9450000 | O24: =SUM(H25:I27) -> 41 | P24: RO | Q24: 2000 LPH | R24: 68
B25: O&M for 1 Year of 190 Plants in Bahawalpur District | E25: ='O&M Analysis'!C77 -> 1.163771e+08 | G25: UF 1000 LPH | H25: 3 | O25: MF | P25: RO | Q25: 4000 LPH | R25: 8
B26: Grand Total | E26: =SUM(E21:E25) -> #REF! | G26: UF 2000 LPH | H26: 33 | I26: 5 | O26: =SUM(H28:I28) -> 0 | P26: UF | Q26: 1000 LPH | R26: 5
B27: Say in million | E27: =E26/1000000 -> #REF! | P27: UF | Q27: 2000 LPH | R27: 21
G28: MF 2000 LPH | P28: UF | Q28: 4000 LPH | R28: 1
A29: Per Plant Value | E29: =E27/H33 -> #REF! | G29: Total | H29: =SUM(H21:H28) -> 63 | I29: =SUM(I21:I28) -> 9 | P29: MF | Q29: 1000 LPH
P30: MF | Q30: 2000 LPH | R30: 9
G31: Total Dysfun | H31: =H29+I29 -> 72 | P31: MF | Q31: 4000 LPH
F32: {=SUM(E22:E23+F21)} -> 0 | G32: Functional | H32: 8 | P32: No of Plants | R32: =SUM(R22:R31) -> 190
F33: =F32/H31 -> 0 | G33: Total Plants | H33: =H32+H31 -> 80
E34: =(E21/43)/1000000 -> #REF! | F34: =F33/1000000 -> 0
H193: s
E203: 24900
E213: 35300
A221: RO Feed Pump Repair 4000 LPH
B223: Repair & maintenance of RO Feed water pump 8000 LPH, for 4000 LPH RO Plant, complete in all respect | E223: 46700
E233: 23950
E243: 36100
...

Sheet RO Rehab 500LPH
A1: =Abstract!A2 -> REHABILITATION OF WATER FILTRATION PLANTS IN DISTRICT BAHAWALPUR | J1: RO | K1: =Abstract!H21 -> 0
J2: Bore | K2: 1
A3: REHABLITATION OF RO PLANT 500 LPH | J3: Abndd | K3: 2
A4: Sr. No. | B4: MRS Ref. # | C4: Description | D4: Unit | E4: Qty. | F4: Unit Rate (PKR) | G4: Amount (PKR) | J4: Dys | K4: 1
A5: 1 | B5: N.S | C5: ='Rate Analysis'!B6 -> Repair & maintenance of Plant Skid frame and Finishing, complete in all respect, inclusive of Carriage to Site and Labor for Installation | D5: p/job | E5: =K1 -> 0 | F5: ='Rate Analysis'!F13 -> 10800 | G5: =F5*E5 -> 0
A6: =A5+1 -> 2 | B6: N.S | C6: ='Rate Analysis'!B18 -> Membranes recovery with chemicals cleaning, including labour & testing, Complete in all respects, inclusive of Carriage to Site and Labor for Installation | D6: p/job | E6: =(K1*50%)*2 -> 0 | F6: ='Rate Analysis'!F25 -> 18000 | G6: =F6*E6 -> 0
A7: =A6+1 -> 3 | B7: N.S | C7: ='Rate Analysis'!B30 -> Supply Installation & Commissioning of Membrane Housing, Complete in all respect | D7: No. | E7: 0 | F7: ='Rate Analysis'!F37 -> 76015 | G7: =F7*E7 -> 0
A8: =A7+1 -> 4 | B8: N.S | C8: ='RA RO500'!B7 -> Supply Installtion and commissioning of RO Plant membranes(4x40), 2 No. complete in all respect | D8: No. | E8: 0 | F8: ='RA RO500'!F13 -> 105255 | G8: =F8*E8 -> 0
A9: =A8+1 -> 5 | B9: N.S | C9: ='RA RO500'!B19 -> Supply Installation and commissioning of RO Feed Pump capacity of 1000 LPH, for 500 LPH RO Plant, complete in all respect | D9: No. | E9: 0 | F9: ='RA RO500'!F25 -> 73095 | G9: =F9*E9 -> 0
A10: =A9+1 -> 6 | B10: N.S | C10: ='RA RO500'!B31 -> Supply, Installation and commissioning of RO High Pressure Pump Capacity of 1000 LPH, for 500 LPH RO Plant, complete in all respect | D10: p/job | E10: 0 | F10: ='RA RO500'!F37 -> 163730 | G10: =F10*E10 -> 0
A11: =A10+1 -> 7 | B11: N.S | C11: ='RA RO500'!B41 -> Repair & maintenance of RO Feed water pump 1000 LPH, for 500 LPH RO Plant, complete in all respect | D11: p/job | E11: 1 | F11: ='RA RO500'!F47 -> 28800 | G11: =F11*E11 -> 28800
A12: =A11+1 -> 8 | B12: N.S | C12: ='RA RO500'!B51 -> Repair & maintenance of RO High Pressure pump 1000 LPH, for 500 LPH RO Plant, complete in all respect | D12: No. | E12: 1 | F12: ='RA RO500'!F57 -> 40800 | G12: =F12*E12 -> 40800
A13: =A12+1 -> 9 | B13: N.S | C13: ='RA RO500'!B75 -> Supply Installation & commissioning of 3inch submersible pump 3HP including supporting clamp, pump coupling, cable clip, delivery pipe, cable complete in all respect. | D13: p/job | E13: 1 | F13: ='RA RO500'!F81 -> 116365 | G13: =F13*E13 -> 116365
A14: =A13+1 -> 10 | B14: N.S | C14: ='Rate Analysis'!B53 -> Supply Installation and Testing of Cartridge Filter complete in all respect | D14: p/job | E14: =K1 -> 0 | F14: ='Rate Analysis'!F59 -> 1510 | G14: =F14*E14 -> 0
A15: =A14+1 -> 11 | B15: N.S | C15: ='Rate Analysis'!B63 -> Supply Installation and Testing of TDS meter complete with all respects | D15: p/job | E15: =K1 -> 0 | F15: ='Rate Analysis'!F69 -> 11695 | G15: =F15*E15 -> 0
A16: =A15+1 -> 12 | B16: N.S | C16: ='Rate Analysis'!B73 -> Supply Installation and Testing of Pressure Switchs complete with all respects | D16: p/job | E16: =K1*60% -> 0 | F16: ='Rate Analysis'!F79 -> 16375 | G16: =F16*E16 -> 0
A17: =A16+1 -> 13 | B17: N.S | C17: ='Rate Analysis'!B97 -> Supply Installation and testing of Rota meter complete in all respect | D17: p/job | E17: =K1*60% -> 0 | F17: ='Rate Analysis'!F103 -> 7015 | G17: =F17*E17 -> 0
A18: =A17+1 -> 14 | B18: N.S | C18: ='Rate Analysis'!B106 -> Supply Installation and Testing of pressure gauges, complete in all respect | D18: p/job | E18: 2 | F18: ='Rate Analysis'!F112 -> 9940 | G18: =F18*E18 -> 19880
A19: =A18+1 -> 15 | B19: N.S | C19: ='Rate Analysis'!B116 -> Supply Installation and testing of Water meter, complete in all respect | D19: p/job | E19: 0 | F19: ='Rate Analysis'!F122 -> 17540 | G19: =F19*E19 -> 0
A20: =A19+1 -> 16 | B20: N.S | C20: ='Rate Analysis'!B143 -> Repair & maintenance of water meter including callibration, complete in all respect | D20: p/job | E20: 1 | F20: ='Rate Analysis'!F150 -> 6000 | G20: =F20*E20 -> 6000
A21: =A20+1 -> 17 | B21: N.S | C21: ='Rate Analysis'!B154 -> Supply Installation and Testing of Solinoid valve complete in all respect | D21: p/job | E21: 1 | F21: ='Rate Analysis'!F160 -> 8770 | G21: =F21*E21 -> 8770
A22: =A21+1 -> 18 | B22: N.S | C22: ='Rate Analysis'!B163 -> Repair & maintenance of Solinoid valve complete in all respect | D22: p/job | E22: 1 | F22: ='Rate Analysis'!F170 -> 4200 | G22: =F22*E22 -> 4200
A23: =A22+1 -> 19 | B23: N.S | C23: ='Rate Analysis'!B191 -> Supply Installation & Commissioning of 3way Multiport Valve, top & bottom distributers, complete in all respect | D23: p/job | E23: 1 | F23: ='Rate Analysis'!F197 -> 40930 | G23: =F23*E23 -> 40930
A24: =A23+1 -> 20 | B24: N.S | C24: ='Rate Analysis'!B201 -> Repair & maintenance of 3way Multiport Valve, top & bottom distributers, complete in all respect | D24: p/job | E24: 1 | F24: ='Rate Analysis'!F208 -> 8400 | G24: =F24*E24 -> 8400
A25: =A24+1 -> 21 | B25: N.S | C25: ='Rate Analysis'!B452 -> 0 | D25: p/job | E25: 1 | F25: ='Rate Analysis'!#REF! -> #REF! | G25: =F25*E25 -> #REF!
A26: =A25+1 -> 22 | B26: N.S | C26: ='Rate Analysis'!B213 -> Supply, installation and Testing of Chemical Dosing Pump, Chlorinator / Liqued Dosing Pump with working pressure 5 - 7 Bar Imported, along with 80 liter capacity tank with all repects.complete in all respect | D26: p/job | E26: 1 | F26: ='Rate Analysis'!F219 -> 69235 | G26: =F26*E26 -> 69235
A27: =A26+1 -> 23 | B27: N.S | C27: ='Rate Analysis'!B235 -> Supply and installation of Water Storage Tank, Capacity 2000 Liters, Material PE, Food Grade, complete in all respects | D27: p/job | E27: 1 | F27: ='Rate Analysis'!F241 -> 31575 | G27: =F27*E27 -> 31575
A28: =A27+1 -> 24 | B28: N.S | C28: ='Rate Analysis'!B247 -> Chemical Cleaning & repair of Water Storage tank, complete in all respects at site | D28: p/job | E28: 1 | F28: ='Rate Analysis'!F254 -> 6000 | G28: =F28*E28 -> 6000
A29: =A28+1 -> 25 | B29: N.S | C29: ='Rate Analysis'!B259 -> Supply and installation of float switch for Water Storage Tank, complete in all respect | D29: kg | E29: 2 | F29: ='Rate Analysis'!F265 -> 2925 | G29: =F29*E29 -> 5850
A30: =A29+1 -> 26 | B30: N.S | C30: ='Rate Analysis'!B280 -> Replacement of Activated Carbon media supply, installation and commissioning complete in all respect NSF Certified, Iodin No 900-1100 | D30: kg | E30: 30 | F30: ='Rate Analysis'!F287 -> 1510 | G30: =F30*E30 -> 45300
A31: =A30+1 -> 27 | B31: N.S | C31: ='Rate Analysis'!B293 -> Replacement of Silica sand media supply, installation and commissioning complete in all respect | D31: kg | E31: 80 | F31: ='Rate Analysis'!F300 -> 110 | G31: =F31*E31 -> 8800
A32: =A31+1 -> 28 | B32: N.S | C32: ='Rate Analysis'!B305 -> Replacement of Natural Gravels media supply, installation and commissioning complete in all respect | D32: p/job | E32: 80 | F32: ='Rate Analysis'!F312 -> 110 | G32: =F32*E32 -> 8800
A33: =A32+1 -> 29 | B33: N.S | C33: ='Rate Analysis'!B341 -> Supply installation and commissioning of UV lamp complete in all respect | D33: p/job | E33: =K1 -> 0 | F33: ='Rate Analysis'!F347 -> 23390 | G33: =F33*E33 -> 0
A34: =A33+1 -> 30 | B34: N.S | C34: ='Rate Analysis'!B352 -> Supply Installation & Commissioning of Manual Valve complete in all respect | D34: p/job | E34: 2 | F34: ='Rate Analysis'!F358 -> 3510 | G34: =F34*E34 -> 7020
A35: =A34+1 -> 31 | B35: N.S | C35: ='Rate Analysis'!B372 -> Repair & maintenance of Pipe and fittings, complete plant fitting in all respect | D35: no. | E35: =K1 -> 0 | F35: ='Rate Analysis'!F379 -> 12000 | G35: =F35*E35 -> 0
A36: =A35+1 -> 32 | B36: N.S | C36: ='Rate Analysis'!B384 -> Supply installation & testing of Plastic water Taps with fussion joint, complete in all respect | D36: p/job | E36: =K1*5 -> 0 | F36: ='Rate Analysis'!F390 -> 585 | G36: =F36*E36 -> 0
A37: =A36+1 -> 33 | B37: N.S | C37: ='Rate Analysis'!B395 -> Repair & maintenance of Plant control panel with PLC & HMI complete in all respect | D37: p/job | E37: =K1 -> 0 | F37: ='Rate Analysis'!F402 -> 36000 | G37: =F37*E37 -> 0
A38: Total Supply & Installtion | G38: =G7+G8+G9+G10+G13+G14+G15+G16+G17+G18+G19+G21+G23+G25+G26+G27+G29+G33+G34+G36 -> #REF! | K38: =SUM(G5:G36) -> #REF!
A39: PRA 5 % (Total Supply & Installtion) | G39: =G38*5% -> #REF! | K39: =K38*5% -> #REF! | L39: =K38+K39 -> #REF!
A40: Total Repair & Maintenance | G40: =G5+G6+G11+G12+G20+G22+G24+G28+G30+G31+G32+G35+G37 -> 157100 | K40: =K38*16% -> #REF! | L40: =K38+K40 -> #REF!
...

Sheet New RO500
A1: ='RO Rehab 500LPH'!A1 -> REHABILITATION OF WATER FILTRATION PLANTS IN DISTRICT BAHAWALPUR
A2: INSTALATION OF RO 500 LPH WFP
A3: Sr, No | B3: Description | C3: Unit | D3: Quantity | E3: Unit Rate (RS) | F3: Amount (RS)
A4: 1 | B4: ='RA RO500'!B63 -> Supply installation and commissioning of 500 L/H Reverse Osmosis (RO) Plant for TDS removal up to 5000 mg/l and inclusive of all taxes conforming to standard specifications according to the Punjab Aab-e-Pak Authority. The specifications along with equipment and accessories properly mounted in the SS frame/skid. | C4: No. | D4: 1 | E4: ='RA RO500'!F69 -> 1198730 | F4: =D4*E4 -> 1198730
B5: Total Capital | F5: =F4 -> 1198730
B6: PRA 5% | F6: =F5*5% -> 59936.5
B7: Grand Total :- | F7: =F5+F6 -> 1258666.5

Sheet R5
A1: =GS!A1 -> PUNJAB SAAF PANI AUTHORITY | H1: =H33 -> 0 | I1: RO | J1: 1
A2: =GS!A2 -> REHABILITATION & O&M OF DYSFUNCTIONAL WATER FILTRATION PLANTS INSTALLED IN DIVISON FAISALABAD | H2: 3 | I2: Bore
A3: =GS!A4:E4 -> BILL OF QUANTITY
A4: Bill No. 1: Rehabilitation of Reverse Osmosis 500 LPH | H4: 3 No., Plant
A5: Sr. No. | B5: MRS Ref. # | C5: Description | D5: Unit | E5: Qty. | F5: Unit Rate (PKR) | G5: Amount (PKR)
A6: 1 | B6: N.S | C6: Rehabilitation of Plant Skid frame and Finishing, complete in all respect, inclusive of Carriage to Site and Labor for Installation Frame: Stainless Steel | D6: Per Plant | E6: 1
A7: 2 | B7: N.S | C7: Supply Installation and commissioning of RO Plant membrane (4x40), including Membrane Housing complete in all respect. Origin: Europe / USA or Equivalent Certification: NSF Pore Size: 0.001 Micron Stablized salt rejection: 99% Capable for TDS: Upto 5000 mg/l Recovery: 15% (each) Life of RO Membrane: 03 to 05 years Pressure Rating: Upto 17 Barg | D7: Per Membrane | E7: 2 | H7: 45000
A8: 3 | B8: N.S | C8: Supply, Installation and commissioning of 1000 LPH High Pressure Pump for 500 LPH RO WFP, complete in all respect Origin: Europe / USA / Japan or Equivalent Discharge: 1000 LPH Operating Head: Up to 16 Barg Pump Type: Vertical / Horizontal High Pressure Pump Impeller material: S.S. 304 Pump Efficiency: > 50% Motor Starter: DOL IP 55 Ambient Temperature Class: 45 degree Celsius | D8: p/job | E8: 1 | I8: 130000
A9: 4 | B9: N.S | C9: Rehabilitation of RO Feed water pump 1000 LPH, for 500 LPH RO Plant, complete in all respect | D9: p/job | E9: 1
A10: 5 | B10: N.S | C10: Supply Installation & commissioning of submersible pump 3HP including supporting clamp with steel cable, pump coupling, cable clip, delivery pipe, electric cable complete in all respect. Origin: Europe / USA/ Asia or Equivalent Minimum Discharge: 2000 LPH Minimum Operation Head: Up to 130 m. Pump Type: Submersible Pump Impeller Type: S.S. 304 Motor Starter: DOL | D10: p/job | E10: 1 | H10: 91365
A11: 6 | B11: N.S | C11: Supply Installation and Testing of Cartridge Filter complete in all respect Size: 20 Inches / As per Flow Porosity: 1-5 micron Material: High pressure Plastic Melt Blown PE | D11: p/job | E11: 1
A12: 7 | B12: N.S | C12: Supply Installation and Testing of Online TDS meter complete with all respects | D12: p/job | E12: 1
A13: 8 | B13: N.S | C13: Supply Installation and Testing of Pressure Switches complete with all respects | D13: p/job | E13: 1
A14: 9 | B14: N.S | C14: Supply Installation and testing of Rota meter complete in all respect Origin: Europe / USA / German / Pakistan or Equivalent Type: Rota Meter / Flow Type Material: Acryclic | D14: p/job | E14: 2
A15: 10 | B15: N.S | C15: Supply Installation and Testing of pressure gauges, complete in all respect | D15: p/job | E15: 3
A16: 11 | B16: N.S | C16: Rehabilitation of Analogue Water meter including callibration, complete in all respect. | D16: p/job | E16: 1
A17: 12 | B17: N.S | C17: Supply Installation and Testing of Solinoid valve complete in all respect | D17: p/job | E17: 2
A18: 13 | B18: N.S | C18: Rehabilitation of Solinoid valve complete in all respect | D18: p/job | E18: 2
A19: 14 | B19: N.S | C19: Supply Installation & Commissioning of 3way Automatic Multiport Valve, top & bottom distributers, complete in all respect | D19: p/job | E19: 1
A20: 15 | B20: N.S | C20: Rehabilitation of 3way Automatic Multiport Valve, top & bottom distributers, complete in all respect | D20: p/job | E20: 1
A21: 16 | B21: N.S | C21: Supply, installation and Testing of Chemical Dosing Pump / Liquid Dosing Pump with working pressure 4 Bar Imported, along with 80 liter capacity tank complete in all respect Origin: Europe / USA / Asia or Equivalent Pressure: 4 bar Tank Size: Maximum 80 liter Chemical Anti Sclanet: Food Grade | D21: p/job | E21: 1
A22: 17 | B22: N.S | C22: Supply and installation of Water Storage Tank, Capacity 2000 Liters, Material PE, Food Grade, 3 to 5 mm wall thickness, weight minimum 32 kg, complete in all respects Capacity : 2000 Litre minimum Material: Plastic food grade | D22: p/job | E22: 1
A23: 18 | B23: N.S | C23: Chemical Cleaning & repair of Water Storage tank, complete in all respects at site | D23: p/job | E23: 1
A24: 19 | B24: N.S | C24: Supply and installation of 2 No. electric float switch for Water Storage Tank, complete in all respect | D24: No. | E24: 1 | H24: =F24/2 -> 0
A25: 20 | B25: N.S | C25: Replacement of Activated Carbon media supply, installation and commissioning complete in all respect NSF Certified, Iodine No 850-1000 Material: Coconut Shell Origin: Sri Lanka / Thailand or Equivalent Size of Media: 1.2 - 1.6 mm Surface Area: 900 m2 / g Bulk Density: 440 - 540 kg / m3 Hardness No: 80 Ash Contents: 5 % Height of Gravel: 200 mm Media Bed Height: > 800 mm | D25: kg | E25: 30 | H25: WASA
A26: 21 | B26: N.S | C26: Replacement of Silica sand media supply, installation and commissioning complete in all respect Material: Quartz Silica Sand Size of Media: 0.85 - 2 mm Cleaning Process: Automatic, through PLC / Time Controller MPV | D26: kg | E26: 90
A27: 22 | B27: N.S | C27: Replacement of Natural Gravels media supply, installation and commissioning complete in all respect Material: Gravel Media | D27: kg | E27: 90
A28: 23 | B28: N.S | C28: Supply installation and commissioning of UV lamp rod with quartz complete in all respect Origin: Europe / USA / German or Equivalent | D28: Per Plant | E28: 1
A29: 24 | B29: N.S | C29: Rehabilitation of Pipe and fittings, complete plant fitting in all respect | D29: Per Plant | E29: 1
A30: 25 | B30: N.S | C30: Supply installation & testing of Plastic water Taps with fusion joint, complete in all respect | D30: p/job | E30: 5
A31: 26 | B31: N.S | C31: Rehabilitation of Plant Control Panel / RO Controller complete in all respect | D31: p/job | E31: 1
A32: 27 | B32: N.S | C32: Supply & Installation of FRP Vessel (Size16 X 65) Origin: Europe / USA / German / China or Equivalent | D32: No. | E32: 1
A33: Grand Total
A34: Per Unit Cost = Grand Total

Sheet Bill No 2 RO 2000 Rehab
A1: ='Bill No 3 UF 1000 Rehab'!A1 -> PUNJAB SAAF PANI AUTHORITY | I1: 21013737 | J1: RO | K1: 1
I2: =G39 -> 957635 | J2: Bore
A3: LAHORE DISTRICT | I3: =I1-I2 -> 20056102 | J3: Dys
A4: =GS!A4:E4 -> BILL OF QUANTITY | J4: fun
A5: Bill No. 2: Rehabilitation of Reverse Osmosis 2 m3/hr
A6: Sr. No. | B6: MRS Ref. # | C6: Description | D6: Unit | E6: Qty. | F6: Unit Rate (PKR) | G6: Amount (PKR) | K6: =GS!#REF! -> #REF!
A7: 1 | B7: N.S | C7: ='Rate Analysis'!B6 -> Repair & maintenance of Plant Skid frame and Finishing, complete in all respect, inclusive of Carriage to Site and Labor for Installation | D7: p/job | E7: 1 | F7: ='Rate Analysis'!F13 -> 10800 | G7: =F7*E7 -> 10800
A8: =A7+1 -> 2 | B8: N.S | C8: ='Rate Analysis'!B18 -> Membranes recovery with chemicals cleaning, including labour & testing, Complete in all respects, inclusive of Carriage to Site and Labor for Installation | D8: p/job | E8: 0 | F8: ='Rate Analysis'!F25 -> 18000 | G8: =F8*E8 -> 0
A9: =A8+1 -> 3 | B9: N.S | C9: ='Rate Analysis'!B30 -> Supply Installation & Commissioning of Membrane Housing, Complete in all respect | D9: No. | E9: 0 | F9: ='Rate Analysis'!F37 -> 76015 | G9: =F9*E9 -> 0
A10: =A9+1 -> 4 | B10: N.S | C10: ='RA RO2000'!B6 -> Supply Installtion and commissioning of RO Plant membranes(4x40), 4 No. complete in all respect. inclusive of Carriage to Site and Labor for Installation | D10: No. | E10: 1 | F10: ='RA RO2000'!F12 -> 421015 | G10: =F10*E10 -> 421015
A11: =A10+1 -> 5 | B11: N.S | C11: ='RA RO2000'!B18 -> Supply Installation and commissioning of RO Feed Pump capacity of 4000 LPH, for 2000 LPH RO Plant, complete in all respect | D11: No. | E11: 0 | F11: ='RA RO2000'!F24 -> 119290 | G11: =F11*E11 -> 0
A12: =A11+1 -> 6 | B12: N.S | C12: ='RA RO2000'!B30 -> Supply, Installation and commissioning of RO High Pressure Pump Capacity of 4000 LPH, for 2000 LPH RO Plant, complete in all respect | D12: p/job | E12: 0 | F12: ='RA RO2000'!F36 -> 239745 | G12: =F12*E12 -> 0
A13: =A12+1 -> 7 | B13: N.S | C13: ='RA RO1000'!B52 -> Repair & maintenance of RO Feed water pump 2000 LPH, for 1000 LPH RO Plant, complete in all respect | D13: p/job | E13: 1 | F13: ='RA RO2000'!F58 -> 28800 | G13: =F13*E13 -> 28800
A14: =A13+1 -> 8 | B14: N.S | C14: ='RA RO2000'!B61 -> Repair & maintenance of RO High Pressure pump 4000 LPH, for 2000 LPH RO Plant, complete in all respect | D14: No. | E14: 1 | F14: ='RA RO2000'!F68 -> 40800 | G14: =F14*E14 -> 40800
A15: =A14+1 -> 9 | B15: N.S | C15: ='RA RO2000'!B95 -> Supply Installation & commissioning of 3inch submersible pump 3HP including supporting clamp, pump coupling, cable clip, delivery pipe, cable complete in all respect. | D15: p/job | E15: 0 | F15: ='RA RO2000'!F101 -> 116365 | G15: =F15*E15 -> 0
A16: =A15+1 -> 10 | B16: N.S | C16: ='Rate Analysis'!B53 -> Supply Installation and Testing of Cartridge Filter complete in all respect | D16: p/job | E16: =K1 -> 1 | F16: ='Rate Analysis'!F59 -> 1510 | G16: =F16*E16 -> 1510
A17: =A16+1 -> 11 | B17: N.S | C17: ='Rate Analysis'!B63 -> Supply Installation and Testing of TDS meter complete with all respects | D17: p/job | E17: =E16 -> 1 | F17: ='Rate Analysis'!F69 -> 11695 | G17: =F17*E17 -> 11695
A18: =A17+1 -> 12 | B18: N.S | C18: ='Rate Analysis'!B73 -> Supply Installation and Testing of Pressure Switchs complete with all respects | D18: p/job | E18: =K1 -> 1 | F18: ='Rate Analysis'!F79 -> 16375 | G18: =F18*E18 -> 16375
A19: =A18+1 -> 13 | B19: N.S | C19: ='Rate Analysis'!B97 -> Supply Installation and testing of Rota meter complete in all respect | D19: p/job | E19: =K1 -> 1 | F19: ='Rate Analysis'!F103 -> 7015 | G19: =F19*E19 -> 7015
A20: =A19+1 -> 14 | B20: N.S | C20: ='Rate Analysis'!B106 -> Supply Installation and Testing of pressure gauges, complete in all respect | D20: p/job | E20: =K1*2 -> 2 | F20: ='Rate Analysis'!F112 -> 9940 | G20: =F20*E20 -> 19880
A21: =A20+1 -> 15 | B21: N.S | C21: ='Rate Analysis'!B116 -> Supply Installation and testing of Water meter, complete in all respect | D21: p/job | E21: 0 | F21: ='Rate Analysis'!F122 -> 17540 | G21: =F21*E21 -> 0
A22: =A21+1 -> 16 | B22: N.S | C22: ='Rate Analysis'!B143 -> Repair & maintenance of water meter including callibration, complete in all respect | D22: p/job | E22: 1 | F22: ='Rate Analysis'!F150 -> 6000 | G22: =F22*E22 -> 6000
A23: =A22+1 -> 17 | B23: N.S | C23: ='Rate Analysis'!B154 -> Supply Installation and Testing of Solinoid valve complete in all respect | D23: p/job | E23: 0 | F23: ='Rate Analysis'!F160 -> 8770 | G23: =F23*E23 -> 0
A24: =A23+1 -> 18 | B24: N.S | C24: ='Rate Analysis'!B163 -> Repair & maintenance of Solinoid valve complete in all respect | D24: p/job | E24: 1 | F24: ='Rate Analysis'!F170 -> 4200 | G24: =F24*E24 -> 4200
A25: =A24+1 -> 19 | B25: N.S | C25: ='Rate Analysis'!B191 -> Supply Installation & Commissioning of 3way Multiport Valve, top & bottom distributers, complete in all respect | D25: p/job | E25: 0 | F25: ='Rate Analysis'!F197 -> 40930 | G25: =F25*E25 -> 0
A26: =A25+1 -> 20 | B26: N.S | C26: ='Rate Analysis'!B201 -> Repair & maintenance of 3way Multiport Valve, top & bottom distributers, complete in all respect | D26: p/job | E26: 2 | F26: ='Rate Analysis'!F208 -> 8400 | G26: =F26*E26 -> 16800
A27: =A26+1 -> 21 | B27: N.S | C27: ='Rate Analysis'!B213 -> Supply, installation and Testing of Chemical Dosing Pump, Chlorinator / Liqued Dosing Pump with working pressure 5 - 7 Bar Imported, along with 80 liter capacity tank with all repects.complete in all respect | D27: p/job | E27: =K1 -> 1 | F27: ='Rate Analysis'!F219 -> 69235 | G27: =F27*E27 -> 69235
A28: =A27+1 -> 22 | B28: N.S | C28: ='Rate Analysis'!B235 -> Supply and installation of Water Storage Tank, Capacity 2000 Liters, Material PE, Food Grade, complete in all respects | D28: p/job | E28: 0 | F28: ='Rate Analysis'!F241 -> 31575 | G28: =F28*E28 -> 0
A29: =A28+1 -> 23 | B29: N.S | C29: ='Rate Analysis'!B247 -> Chemical Cleaning & repair of Water Storage tank, complete in all respects at site | D29: p/job | E29: 1 | F29: ='Rate Analysis'!F254 -> 6000 | G29: =F29*E29 -> 6000
A30: =A29+1 -> 24 | B30: N.S | C30: ='Rate Analysis'!B259 -> Supply and installation of float switch for Water Storage Tank, complete in all respect | D30: No. | E30: 1 | F30: ='Rate Analysis'!F265 -> 2925 | G30: =F30*E30 -> 2925
A31: =A30+1 -> 25 | B31: N.S | C31: ='Rate Analysis'!B280 -> Replacement of Activated Carbon media supply, installation and commissioning complete in all respect NSF Certified, Iodin No 900-1100 | D31: kg | E31: =160*(K1*80%) -> 128 | F31: ='Rate Analysis'!F287 -> 1510 | G31: =F31*E31 -> 193280
A32: =A31+1 -> 26 | B32: N.S | C32: ='Rate Analysis'!B293 -> Replacement of Silica sand media supply, installation and commissioning complete in all respect | D32: kg | E32: =160*(K1*80%) -> 128 | F32: ='Rate Analysis'!F300 -> 110 | G32: =F32*E32 -> 14080
A33: =A32+1 -> 27 | B33: N.S | C33: ='Rate Analysis'!B305 -> Replacement of Natural Gravels media supply, installation and commissioning complete in all respect | D33: kg | E33: =160*(K1*80%) -> 128 | F33: ='Rate Analysis'!F312 -> 110 | G33: =F33*E33 -> 14080
A34: =A33+1 -> 28 | B34: N.S | C34: ='Rate Analysis'!B341 -> Supply installation and commissioning of UV lamp complete in all respect | D34: p/job | E34: =K1 -> 1 | F34: ='Rate Analysis'!F347 -> 23390 | G34: =F34*E34 -> 23390
A35: =A34+1 -> 29 | B35: N.S | C35: ='Rate Analysis'!B352 -> Supply Installation & Commissioning of Manual Valve complete in all respect | D35: p/job | E35: 0 | F35: ='Rate Analysis'!F358 -> 3510 | G35: =F35*E35 -> 0
A36: =A35+1 -> 30 | B36: N.S | C36: ='Rate Analysis'!B372 -> Repair & maintenance of Pipe and fittings, complete plant fitting in all respect | D36: no. | E36: 1 | F36: ='Rate Analysis'!F379 -> 12000 | G36: =F36*E36 -> 12000
A37: =A36+1 -> 31 | B37: N.S | C37: ='Rate Analysis'!B384 -> Supply installation & testing of Plastic water Taps with fussion joint, complete in all respect | D37: p/job | E37: =K1*3 -> 3 | F37: ='Rate Analysis'!F390 -> 585 | G37: =F37*E37 -> 1755
A38: =A37+1 -> 32 | B38: N.S | C38: ='Rate Analysis'!B395 -> Repair & maintenance of Plant control panel with PLC & HMI complete in all respect | D38: p/job | E38: =K1 -> 1 | F38: ='Rate Analysis'!F402 -> 36000 | G38: =F38*E38 -> 36000
A39: Grand Total | G39: =SUM(G7:G38) -> 957635
A40: Total Supply & Installtion | G40: =G9+G10+G11+G12+G15+G16+G17+G18+G19+G20+G21+G23+G25+#REF!+#REF!+G27+G28+G30+G34+G35+G37 -> #REF! | K40: =SUM(G7:G37) -> 921635
...

Sheet Bill No 3 UF 1000 Rehab
A1: ='Bill no 3 RO 1000 New'!A1 -> PUNJAB SAAF PANI AUTHORITY | I1: 3460870 | J1: UF | K1: =GS!#REF! -> #REF!
I2: =G36 -> 0 | J2: abnd | K2: 0
A3: LAHORE DISTRICT | I3: =I1-I2 -> 3460870 | J3: dys | K3: 2
A4: =GS!A4:E4 -> BILL OF QUANTITY
A5: Bill No. 3: Rehabilitation of Ultra Filtration 1 m3/hr
A6: Sr. No. | B6: MRS Ref. # | C6: Description | D6: Unit | E6: Qty. | F6: Unit Rate (PKR) | G6: Amount (PKR)
A7: 1 | B7: N.S | C7: ='Rate Analysis'!B6 -> Repair & maintenance of Plant Skid frame and Finishing, complete in all respect, inclusive of Carriage to Site and Labor for Installation | D7: p/job | E7: 3 | F7: ='Rate Analysis'!F13 -> 10800 | G7: =F7*E7 -> 32400
A8: 2 | B8: N.S | C8: ='Rate Analysis'!B18 -> Membranes recovery with chemicals cleaning, including labour & testing, Complete in all respects, inclusive of Carriage to Site and Labor for Installation | D8: p/job | E8: 2 | F8: ='Rate Analysis'!F25 -> 18000 | G8: =F8*E8 -> 36000
A9: 3 | B9: N.S | C9: ='RA UF1000'!B18 -> Supply Installation and commissioning of UF Feed Pump capacity of 1000 LPH, for 1000 LPH UF Plant, complete in all respect | D9: No. | E9: 1 | F9: ='RA UF1000'!F24 -> 73095 | G9: =F9*E9 -> 73095
A10: =A9+1 -> 4 | B10: N.S | C10: ='RA UF1000'!B28 -> Repair & maintenance of UF Feed water pump 1000 LPH, for 1000 LPH UF Plant, complete in all respect | D10: p/job | E10: 1 | F10: ='RA UF1000'!F34 -> 28800 | G10: =F10*E10 -> 28800
A11: =A10+1 -> 5 | B11: N.S | C11: ='RA UF1000'!B66 -> Supply Installation & commissioning of 3inch submersible pump 3HP including supporting clamp, pump coupling, cable clip, delivery pipe, cable complete in all respect. | D11: p/job | E11: 1 | F11: ='RA UF1000'!F72 -> 116365 | G11: =F11*E11 -> 116365
A12: =A11+1 -> 6 | B12: N.S | C12: ='Rate Analysis'!B438 -> Supply and installation of safety filter strainer | D12: p/job | E12: 9 | F12: ='Rate Analysis'!F444 -> 1405 | G12: =F12*E12 -> 12645
A13: =A12+1 -> 7 | B13: N.S | C13: ='Rate Analysis'!B63 -> Supply Installation and Testing of TDS meter complete with all respects | D13: p/job | E13: =K1 -> #REF! | F13: ='Rate Analysis'!F69 -> 11695 | G13: =F13*E13 -> #REF!
A14: =A13+1 -> 8 | B14: N.S | C14: ='Rate Analysis'!B73 -> Supply Installation and Testing of Pressure Switchs complete with all respects | D14: p/job | E14: 9 | F14: ='Rate Analysis'!F79 -> 16375 | G14: =F14*E14 -> 147375
A15: =A14+1 -> 9 | B15: N.S | C15: ='Rate Analysis'!B97 -> Supply Installation and testing of Rota meter complete in all respect | D15: p/job | E15: 9 | F15: ='Rate Analysis'!F103 -> 7015 | G15: =F15*E15 -> 63135
A16: =A15+1 -> 10 | B16: N.S | C16: ='Rate Analysis'!B106 -> Supply Installation and Testing of pressure gauges, complete in all respect | D16: p/job | E16: 18 | F16: ='Rate Analysis'!F112 -> 9940 | G16: =F16*E16 -> 178920
A17: =A16+1 -> 11 | B17: N.S | C17: ='Rate Analysis'!B116 -> Supply Installation and testing of Water meter, complete in all respect | D17: p/job | E17: 3 | F17: ='Rate Analysis'!F122 -> 17540 | G17: =F17*E17 -> 52620
A18: =A17+1 -> 12 | B18: N.S | C18: ='Rate Analysis'!B143 -> Repair & maintenance of water meter including callibration, complete in all respect | D18: p/job | E18: 5 | F18: ='Rate Analysis'!F150 -> 6000 | G18: =F18*E18 -> 30000
A19: =A18+1 -> 13 | B19: N.S | C19: ='Rate Analysis'!B154 -> Supply Installation and Testing of Solinoid valve complete in all respect | D19: p/job | E19: 6 | F19: ='Rate Analysis'!F160 -> 8770 | G19: =F19*E19 -> 52620
A20: =A19+1 -> 14 | B20: N.S | C20: ='Rate Analysis'!B163 -> Repair & maintenance of Solinoid valve complete in all respect | D20: p/job | E20: 5 | F20: ='Rate Analysis'!F170 -> 4200 | G20: =F20*E20 -> 21000
A21: =A20+1 -> 15 | B21: N.S | C21: ='Rate Analysis'!B191 -> Supply Installation & Commissioning of 3way Multiport Valve, top & bottom distributers, complete in all respect | D21: p/job | E21: 3 | F21: ='Rate Analysis'!F197 -> 40930 | G21: =F21*E21 -> 122790
A22: =A21+1 -> 16 | B22: N.S | C22: ='Rate Analysis'!B201 -> Repair & maintenance of 3way Multiport Valve, top & bottom distributers, complete in all respect | D22: p/job | E22: 5 | F22: ='Rate Analysis'!F208 -> 8400 | G22: =F22*E22 -> 42000
A23: =A22+1 -> 17 | B23: N.S | C23: ='Rate Analysis'!B213 -> Supply, installation and Testing of Chemical Dosing Pump, Chlorinator / Liqued Dosing Pump with working pressure 5 - 7 Bar Imported, along with 80 liter capacity tank with all repects.complete in all respect | D23: p/job | E23: =K1 -> #REF! | F23: ='Rate Analysis'!F219 -> 69235 | G23: =F23*E23 -> #REF!
A24: =A23+1 -> 18 | B24: N.S | C24: ='Rate Analysis'!B235 -> Supply and installation of Water Storage Tank, Capacity 2000 Liters, Material PE, Food Grade, complete in all respects | D24: p/job | E24: 1 | F24: ='Rate Analysis'!F241 -> 31575 | G24: =F24*E24 -> 31575
A25: =A24+1 -> 19 | B25: N.S | C25: ='Rate Analysis'!B247 -> Chemical Cleaning & repair of Water Storage tank, complete in all respects at site | D25: p/job | E25: 17 | F25: ='Rate Analysis'!F254 -> 6000 | G25: =F25*E25 -> 102000
A26: =A25+1 -> 20 | B26: N.S | C26: ='Rate Analysis'!B259 -> Supply and installation of float switch for Water Storage Tank, complete in all respect | D26: kg | E26: 2 | F26: ='Rate Analysis'!F265 -> 2925 | G26: =F26*E26 -> 5850
A27: =A26+1 -> 21 | B27: N.S | C27: ='Rate Analysis'!B280 -> Replacement of Activated Carbon media supply, installation and commissioning complete in all respect NSF Certified, Iodin No 900-1100 | D27: kg | E27: =50*(K1*50%) -> #REF! | F27: ='Rate Analysis'!F287 -> 1510 | G27: =F27*E27 -> #REF!
A28: =A27+1 -> 22 | B28: N.S | C28: ='Rate Analysis'!B293 -> Replacement of Silica sand media supply, installation and commissioning complete in all respect | D28: kg | E28: =160*(K1*50%) -> #REF! | F28: ='Rate Analysis'!F300 -> 110 | G28: =F28*E28 -> #REF!
A29: =A28+1 -> 23 | B29: N.S | C29: ='Rate Analysis'!B305 -> Replacement of Natural Gravels media supply, installation and commissioning complete in all respect | D29: p/job | E29: =160*(K1*50%) -> #REF! | F29: ='Rate Analysis'!F312 -> 110 | G29: =F29*E29 -> #REF!
A30: =A29+1 -> 24 | B30: N.S | C30: ='Rate Analysis'!B328 -> Replacement of Granular Feric Oxide use for druinking water treatment with oxidation capavity of AS3 to AS5, commissioning complete in all respect | D30: kg | E30: =160*1 -> 160 | F30: ='Rate Analysis'!F335 -> 2640 | G30: =F30*E30 -> 422400
A31: =A30+1 -> 25 | B31: N.S | C31: ='Rate Analysis'!B341 -> Supply installation and commissioning of UV lamp complete in all respect | D31: p/job | E31: =K1 -> #REF! | F31: ='Rate Analysis'!F347 -> 23390 | G31: =F31*E31 -> #REF!
A32: =A31+1 -> 26 | B32: N.S | C32: ='Rate Analysis'!B352 -> Supply Installation & Commissioning of Manual Valve complete in all respect | D32: p/job | E32: 1 | F32: ='Rate Analysis'!F358 -> 3510 | G32: =F32*E32 -> 3510
A33: =A32+1 -> 27 | B33: N.S | C33: ='Rate Analysis'!B372 -> Repair & maintenance of Pipe and fittings, complete plant fitting in all respect | D33: no. | E33: =K1 -> #REF! | F33: ='Rate Analysis'!F379 -> 12000 | G33: =F33*E33 -> #REF!
A34: =A33+1 -> 28 | B34: N.S | C34: ='Rate Analysis'!B384 -> Supply installation & testing of Plastic water Taps with fussion joint, complete in all respect | D34: p/job | E34: =K1*3 -> #REF! | F34: ='Rate Analysis'!F390 -> 585 | G34: =F34*E34 -> #REF!
A35: =A34+1 -> 29 | B35: N.S | C35: ='Rate Analysis'!B395 -> Repair & maintenance of Plant control panel with PLC & HMI complete in all respect | D35: p/job | E35: =K1 -> #REF! | F35: ='Rate Analysis'!F402 -> 36000 | G35: =F35*E35 -> #REF!
A36: Grand Total | G36: 0
A37: Total Supply & Installtion | G37: =#REF!+#REF!+G9+G11+G12+G13+G14+G15+G16+G17+G19+G21+#REF!+G23+G24+G26+G31+G32+G34 -> #REF! | K37: =SUM(G7:G34) -> #REF!
A38: PRA 5 % (Total Supply & Installtion) | G38: =G37*5% -> #REF! | K38: =K37*5% -> #REF! | L38: =K37+K38 -> #REF!
A39: Total Repair & Maintenance | G39: =G7+G8+G10+G18+G20+G22+G25+G27+G28+G29+G30+G33+G35 -> #REF! | K39: =K37*16% -> #REF! | L39: =K37+K39 -> #REF!
A40: PRA 16 % (Total Repair & Maintenance) | G40: =G39*16% -> #REF!
...

Sheet R1
A1: ='R5'!A1:G2 -> PUNJAB SAAF PANI AUTHORITY | H1: =H37 -> 0 | I1: RO | J1: 50
A2: ='R5'!A2:G2 -> REHABILITATION & O&M OF DYSFUNCTIONAL WATER FILTRATION PLANTS INSTALLED IN DIVISON FAISALABAD | H2: =G37 -> 0 | I2: Bore
A3: ='R5'!A3:G3 -> BILL OF QUANTITY
A4: Bill No. 2: Rehabilitation of Reverse Osmosis 1000 LPH
A5: Sr. No. | B5: MRS Ref. # | C5: Description | D5: Unit | E5: Qty. | F5: Unit Rate (PKR) | G5: Amount (PKR)
A6: 1 | B6: N.S | C6: Rehabilitation of Plant Skid frame and Finishing, complete in all respect, inclusive of Carriage to Site and Labor for Installation Frame: Stainless Steel | D6: Per Plant | E6: 30 | H6: 10800
A7: 2 | B7: N.S | C7: Membranes recovery with chemicals cleaning, including labour & testing, Complete in all respects, inclusive of Carriage to Site and Labor for Installation | D7: Per Plant | E7: 20 | H7: 19000
A8: 3 | B8: N.S | C8: Supply Installation and commissioning of RO Plant membrane (4x40), including Membrane Housing complete in all respect. Origin: Europe / USA or Equivalent Certification: NSF Pore Size: 0.001 Micron Stablized salt rejection: 99% Capable for TDS: Upto 5000 mg/l Recovery: 15% (each) Life of RO Membrane: 03 to 05 years Pressure Rating: Upto 17 Barg | D8: Per Membrane | E8: 80 | H8: =210510/4 -> 52627.5 | I8: =40/4 -> 10 | J8: =40/4 -> 10 | K8: =80/4 -> 20
A9: 4 | B9: N.S | C9: Supply Installation and commissioning of 2000 LPH Feed Pump for 1000 LPH RO WFP, complete in all respect Discharge: 2000 LPH Minimum Operation Head: 04 Barg Maximum. Origin: Europe / USA / China or Equivalent Pump Type: Vertical / Horizontal Low Pressure Pump Impeller Type: S.S. 304 Operating Head: Up to 06 Barg Pump Efficiency: ≥ 40% Motor Starter: DOL | D9: No. | E9: 15 | H9: 94745 | I9: 80000
A10: 5 | B10: N.S | C10: Supply, Installation and commissioning of 2000 LPH High Pressure Pump for 1000 LPH RO WFP, complete in all respect Origin: Europe / USA / Japan or Equivalent Discharge: 2000 LPH Operating Head: Up to 16 Barg Pump Type: Vertical / Horizontal High Pressure Pump Impeller material: S.S. 304 Pump Efficiency: > 50% Motor Starter: DOL IP 55 Ambient Temperature Class: 45 degree Celsius | D10: p/job | E10: 15 | H10: 204660 | I10: 130000
A11: 6 | B11: N.S | C11: Rehabilitation of RO Feed water pump 2000 LPH, for 1000 LPH RO Plant, complete in all respect | D11: p/job | E11: 35 | H11: 18800
A12: 7 | B12: N.S | C12: Rehabilitation of RO High Pressure pump 2000 LPH, for 1000 LPH RO Plant, complete in all respect | D12: p/job | E12: 35 | H12: 35800
A13: 8 | B13: N.S | C13: Supply Installation & commissioning of submersible pump 3HP including supporting clamp with steel cable, pump coupling, cable clip, delivery pipe, electric cable complete in all respect. Origin: Europe / USA/ Asia or Equivalent Minimum Discharge: 2000 LPH Minimum Operation Head: Up to 130 m. Pump Type: Submersible Pump Impeller Type: S.S. 304 Motor Starter: DOL | D13: p/job | E13: 25 | H13: 91365
A14: 9 | B14: N.S | C14: Supply Installation and Testing of Cartridge Filter complete in all respect Size: 20 Inches / As per Flow Porosity: 1-5 micron Material: High pressure Plastic Melt Blown PE | D14: p/job | E14: =J1*100% -> 50 | H14: 1510
A15: 10 | B15: N.S | C15: Supply Installation and Testing of Online TDS meter complete with all respects | D15: p/job | E15: =J1 -> 50 | H15: 8695
A16: 11 | B16: N.S | C16: Supply Installation and Testing of Pressure Switches complete with all respects | D16: p/job | E16: =J1 -> 50 | H16: 6375
A17: 12 | B17: N.S | C17: Supply Installation and testing of Rota meter complete in all respect Origin: Europe / USA / German / Pakistan or Equivalent Type: Rota Meter / Flow Type Material: Acryclic | D17: p/job | E17: =J1 -> 50 | H17: 5117
A18: 13 | B18: N.S | C18: Supply Installation and Testing of pressure gauges, complete in all respect | D18: p/job | E18: =J1*4 -> 200 | H18: 3400
A19: 14 | B19: N.S | C19: Supply Installation and testing of Analogue Water meter, complete in all respect | D19: p/job | E19: 25 | H19: 17540
A20: 15 | B20: N.S | C20: Rehabilitation of analogue water meter including callibration, complete in all respect | D20: p/job | E20: 25 | H20: 6000
A21: 16 | B21: N.S | C21: Supply Installation and Testing of Solinoid valve complete in all respect | D21: p/job | E21: 50 | H21: 8500
A22: 17 | B22: N.S | C22: Rehabilitation of Solinoid valve complete in all respect | D22: p/job | E22: 60 | H22: 3200
A23: 18 | B23: N.S | C23: Supply Installation & Commissioning of 3way Automatic Multiport Valve, top & bottom distributers, complete in all respect | D23: p/job | E23: 30 | H23: 40930
A24: 19 | B24: N.S | C24: Rehabilitation of 3way Automatic Multiport Valve, top & bottom distributers, complete in all respect | D24: p/job | E24: 50 | H24: 8400
A25: 20 | B25: N.S | C25: Supply, installation and Testing of Chemical Dosing Pump / Liquid Dosing Pump with working pressure 5 - 7 Bar Imported, along with 80 liter capacity tank complete in all respect Origin: Europe / USA / Asia or Equivalent Pressure: 5 -7 bar Tank Size: Maximum 80 liter Chemical Anti Sclanet: Food Grade | D25: p/job | E25: 25 | H25: 69235
A26: 21 | B26: N.S | C26: Supply and installation of Water Storage Tank, Capacity 2000 Liters, Material PE, Food Grade, 3 to 5 mm wall thickness, weight minimum 32 kg, complete in all respects Capacity : 2000 Litre minimum Material: Plastic food grade | D26: p/job | E26: 35 | H26: 45575
A27: 22 | B27: N.S | C27: Chemical Cleaning of Water Storage tank, complete in all respects at site | D27: p/job | E27: =(J1*2)-E26 -> 65 | H27: 2500
